import { describe, it, expect, beforeEach, vi } from 'vitest'
import { errorHandler, errorBoundary, errorRecovery } from '@/views/utils/errorHandler'

// Mock error handling functions
const handleNetworkError = async (operation: () => Promise<any>): Promise<any> => {
  try {
    return await operation()
  } catch (error) {
    if (error instanceof Error && error.message.includes('Network')) {
      throw new Error('Network connection failed. Please check your internet connection.')
    }
    throw error
  }
}

const handleValidationError = (error: Error): string => {
  if (error.message.includes('validation')) {
    return 'Please check your input and try again.'
  }
  return error.message
}

const handleTaskError = (error: Error): string => {
  if (error.message.includes('not found')) {
    return 'Task not found.'
  }
  if (error.message.includes('permission')) {
    return 'You do not have permission to perform this action.'
  }
  if (error.message.includes('running')) {
    return 'This task is currently running and cannot be modified.'
  }
  return error.message
}

const retryOperation = async <T>(
  operation: () => Promise<T>,
  maxRetries: number = 3
): Promise<T> => {
  let lastError: Error
  
  for (let attempt = 0; attempt <= maxRetries; attempt++) {
    try {
      return await operation()
    } catch (error) {
      lastError = error as Error
      
      if (attempt === maxRetries) {
        throw lastError
      }
      
      // Wait before retry
      await new Promise(resolve => setTimeout(resolve, 1000 * (attempt + 1)))
    }
  }
  
  throw lastError!
}

describe('Email Extraction Error Handling Tests', () => {
  beforeEach(() => {
    errorHandler.clearErrors()
  })

  describe('Network Error Handling', () => {
    it('should handle network errors gracefully', async () => {
      const failingOperation = () => Promise.reject(new Error('Network error'))
      
      await expect(handleNetworkError(failingOperation)).rejects.toThrow(
        'Network connection failed. Please check your internet connection.'
      )
    })

    it('should pass through non-network errors', async () => {
      const failingOperation = () => Promise.reject(new Error('Validation error'))
      
      await expect(handleNetworkError(failingOperation)).rejects.toThrow('Validation error')
    })

    it('should handle successful operations', async () => {
      const successfulOperation = () => Promise.resolve('Success')
      
      const result = await handleNetworkError(successfulOperation)
      expect(result).toBe('Success')
    })
  })

  describe('Validation Error Handling', () => {
    it('should provide user-friendly validation error messages', () => {
      const validationError = new Error('validation failed')
      const result = handleValidationError(validationError)
      
      expect(result).toBe('Please check your input and try again.')
    })

    it('should pass through non-validation errors', () => {
      const otherError = new Error('Some other error')
      const result = handleValidationError(otherError)
      
      expect(result).toBe('Some other error')
    })
  })

  describe('Task Error Handling', () => {
    it('should handle task not found errors', () => {
      const notFoundError = new Error('Task not found')
      const result = handleTaskError(notFoundError)
      
      expect(result).toBe('Task not found.')
    })

    it('should handle permission errors', () => {
      const permissionError = new Error('permission denied')
      const result = handleTaskError(permissionError)
      
      expect(result).toBe('You do not have permission to perform this action.')
    })

    it('should handle running task errors', () => {
      const runningError = new Error('Task is running')
      const result = handleTaskError(runningError)
      
      expect(result).toBe('This task is currently running and cannot be modified.')
    })

    it('should pass through other errors', () => {
      const otherError = new Error('Unknown error')
      const result = handleTaskError(otherError)
      
      expect(result).toBe('Unknown error')
    })
  })

  describe('Retry Mechanism', () => {
    it('should retry failed operations', async () => {
      let attempts = 0
      const failingOperation = () => {
        attempts++
        if (attempts < 3) {
          return Promise.reject(new Error('Temporary failure'))
        }
        return Promise.resolve('Success')
      }
      
      const result = await retryOperation(failingOperation, 3)
      
      expect(result).toBe('Success')
      expect(attempts).toBe(3)
    })

    it('should fail after max retries', async () => {
      const alwaysFailingOperation = () => Promise.reject(new Error('Persistent failure'))
      
      await expect(retryOperation(alwaysFailingOperation, 2)).rejects.toThrow('Persistent failure')
    })

    it('should succeed on first attempt', async () => {
      const successfulOperation = () => Promise.resolve('Success')
      
      const result = await retryOperation(successfulOperation)
      
      expect(result).toBe('Success')
    })
  })

  describe('Error Handler Integration', () => {
    it('should add errors to handler', () => {
      const errorId = errorHandler.addError({
        message: 'Test error',
        type: 'error',
        recoverable: true
      })
      
      const errors = errorHandler.getActiveErrors()
      expect(errors).toHaveLength(1)
      expect(errors[0].id).toBe(errorId)
      expect(errors[0].message).toBe('Test error')
    })

    it('should provide user-friendly error messages', () => {
      const errorId = errorHandler.addError({
        message: 'Network Error',
        type: 'error',
        recoverable: true
      }, { userFriendly: true })
      
      const errors = errorHandler.getActiveErrors()
      expect(errors[0].userFriendlyMessage).toContain('Network connection failed')
    })

    it('should handle offline errors', () => {
      // Mock offline status
      Object.defineProperty(navigator, 'onLine', {
        value: false,
        writable: true
      })
      
      const errorId = errorHandler.addError({
        message: 'Request failed',
        type: 'error',
        recoverable: true
      })
      
      const errors = errorHandler.getActiveErrors()
      expect(errors[0].isOffline).toBe(true)
    })
  })

  describe('Error Boundary', () => {
    it('should wrap async operations with error handling', async () => {
      const failingOperation = () => Promise.reject(new Error('Test error'))
      
      const result = await errorBoundary.wrapAsync(failingOperation, {
        showDialog: true,
        retryable: true
      })
      
      expect(result).toBeNull()
      
      const errors = errorHandler.getActiveErrors()
      expect(errors).toHaveLength(1)
      expect(errors[0].message).toBe('Test error')
    })

    it('should wrap sync operations with error handling', () => {
      const failingOperation = () => {
        throw new Error('Sync error')
      }
      
      const result = errorBoundary.wrapSync(failingOperation, {
        showDialog: true
      })
      
      expect(result).toBeNull()
      
      const errors = errorHandler.getActiveErrors()
      expect(errors).toHaveLength(1)
      expect(errors[0].message).toBe('Sync error')
    })

    it('should pass through successful operations', async () => {
      const successfulOperation = () => Promise.resolve('Success')
      
      const result = await errorBoundary.wrapAsync(successfulOperation)
      
      expect(result).toBe('Success')
    })
  })

  describe('Error Recovery', () => {
    it('should retry with exponential backoff', async () => {
      let attempts = 0
      const operation = () => {
        attempts++
        if (attempts < 3) {
          return Promise.reject(new Error('Temporary failure'))
        }
        return Promise.resolve('Success')
      }
      
      const result = await errorRecovery.retryWithBackoff(operation, 3, 100)
      
      expect(result).toBe('Success')
      expect(attempts).toBe(3)
    })

    it('should fail after max retries with backoff', async () => {
      const alwaysFailingOperation = () => Promise.reject(new Error('Persistent failure'))
      
      await expect(errorRecovery.retryWithBackoff(alwaysFailingOperation, 2, 100))
        .rejects.toThrow('Persistent failure')
    })
  })

  describe('Edge Cases', () => {
    it('should handle undefined errors', () => {
      const errorId = errorHandler.addError({
        message: undefined as any,
        type: 'error',
        recoverable: false
      })
      
      const errors = errorHandler.getActiveErrors()
      expect(errors[0].message).toBeUndefined()
    })

    it('should handle null errors', () => {
      const errorId = errorHandler.addError({
        message: null as any,
        type: 'error',
        recoverable: false
      })
      
      const errors = errorHandler.getActiveErrors()
      expect(errors[0].message).toBeNull()
    })

    it('should handle empty error messages', () => {
      const errorId = errorHandler.addError({
        message: '',
        type: 'error',
        recoverable: false
      })
      
      const errors = errorHandler.getActiveErrors()
      expect(errors[0].message).toBe('')
    })

    it('should handle very long error messages', () => {
      const longMessage = 'A'.repeat(10000)
      const errorId = errorHandler.addError({
        message: longMessage,
        type: 'error',
        recoverable: false
      })
      
      const errors = errorHandler.getActiveErrors()
      expect(errors[0].message).toBe(longMessage)
    })
  })

  describe('Error Cleanup', () => {
    it('should remove errors by ID', () => {
      const errorId = errorHandler.addError({
        message: 'Test error',
        type: 'error',
        recoverable: false
      })
      
      expect(errorHandler.getActiveErrors()).toHaveLength(1)
      
      errorHandler.removeError(errorId)
      
      expect(errorHandler.getActiveErrors()).toHaveLength(0)
    })

    it('should clear all errors', () => {
      errorHandler.addError({
        message: 'Error 1',
        type: 'error',
        recoverable: false
      })
      
      errorHandler.addError({
        message: 'Error 2',
        type: 'warning',
        recoverable: true
      })
      
      expect(errorHandler.getActiveErrors()).toHaveLength(2)
      
      errorHandler.clearErrors()
      
      expect(errorHandler.getActiveErrors()).toHaveLength(0)
    })

    it('should get errors by type', () => {
      errorHandler.addError({
        message: 'Error 1',
        type: 'error',
        recoverable: false
      })
      
      errorHandler.addError({
        message: 'Warning 1',
        type: 'warning',
        recoverable: true
      })
      
      errorHandler.addError({
        message: 'Error 2',
        type: 'error',
        recoverable: false
      })
      
      const errorErrors = errorHandler.getErrorsByType('error')
      const warningErrors = errorHandler.getErrorsByType('warning')
      
      expect(errorErrors).toHaveLength(2)
      expect(warningErrors).toHaveLength(1)
    })
  })
}) 